Workbook

Sheet Инструкция
B2: ФИНАНСОВАЯ МОДЕЛЬ — шаурма-киоск в Лондоне (московский стиль)
B5: Проект: небольшой уличный киоск (несколько кв. м), шаурма на курице, майонезный соус, армянский лаваш.
B6: Локация базового сценария: Kensington & Chelsea (Челси / Саут-Кенсингтон), премиальное позиционирование.
B7: Валюта: фунт стерлингов (£). Все суммы указаны БЕЗ НДС, если не оговорено иное. Налоговый год — 2026/27.
B9: КАК ПОЛЬЗОВАТЬСЯ:
B10: • Меняйте только СИНИЕ ячейки (это вводные допущения). Все остальные значения считаются формулами.
B11: • Начните с листа «Допущения» — там собраны все ключевые параметры и ставки налогов со ссылками на источники.
B12: • Лист «Меню и фудкост» — оптовая себестоимость одной порции (bill of materials).
B13: • Листы «Выручка», «Персонал», «Опер. расходы», «Стартовые вложения» — драйверы модели.
B14: • Итоги: «P&L (3 года)», «Cash flow», «Безубыточность», «Налоги».
B16: ЛЕГЕНДА ЦВЕТОВ:
B17: • Синий шрифт — редактируемая вводная (input).
... B29: в конкретном боро и проконсультируйтесь с бухгалтером (accountant) и HMRC.

Sheet Допущения
A1: ДОПУЩЕНИЯ / INPUTS — Шаурма-киоск, Лондон (2026/27)
A2: Синие ячейки — редактируемые вводные. Суммы в £ без НДС, если не указано иное.
A3: Параметр | B3: Значение | C3: Ед. | D3: Комментарий / источник
A4: 1. ПРОДАЖИ
A5: Порций (шаурмы) в день — база | B5: 90 | C5: шт | D5: Средний поток заказов; варьируется в «Безубыточности».
A6: Средний чек (заказ), с НДС | B6: 9.5 | C6: £ | D6: Шаурма + напиток/допы. Премиальное позиционирование.
A7: Ставка НДС (горячая еда навынос) | B7: 0.2 | D7: HMRC VAT Notice 701/14 — стандартная ставка 20%.
A8: Годовой рост (Год 2, Год 3) | B8: 0.05 | D8: Инфляция цен/объёма для прогноза.
A10: 2. ПЕРСОНАЛ
A11: Часы работы точки в день | B11: 12 | C11: ч | D11: Напр. 10:00–22:00.
A12: Персонала одновременно (среднее) | B12: 1.6 | C12: чел | D12: 1 в непик, 2 в пик.
A13: Человеко-часов в день | B13: =B11*B12 | C13: ч | D13: =часы × персонал (расчёт).
A14: Ставка оплаты труда | B14: 12.71 | C14: £/ч | D14: National Living Wage 21+ с апр.2026. London Living Wage 14.80 (добров.).
A15: Кол-во оформленных сотрудников | B15: 3 | C15: чел | D15: Для порогов NIC и пенсии (совместители).
A16: Employer NIC (соц. взнос работодателя) | B16: 0.15 | D16: 15% сверх Secondary Threshold с 2025/26.
A17: Secondary Threshold (порог NIC) | B17: 5000 | C17: £/год | D17: £5,000 на сотрудника (2025/26–2027/28).
A18: Employment Allowance | B18: 10500 | C18: £/год | D18: Вычет из NIC работодателя, до £10,500.
A19: Пенсия — взнос работодателя | B19: 0.03 | D19: Auto-enrolment, минимум 3% работодателя.
A20: Пенсия — нижний порог (qualifying) | B20: 6240 | C20: £/год | D20: Взносы на заработок сверх £6,240 (2026/27).
A22: 3. АРЕНДА И ЛИЦЕНЗИИ
A23: Аренда места / pitch fee | B23: 2200 | C23: £/мес | D23: Street food London ~£2,000/мес; RBKC/Челси — премия.
A24: Депозит (месяцев аренды) | B24: 2 | C24: мес | D24: Обычно 1–3 месяца.
A25: Лицензия street trading (в год) | B25: 1200 | C25: £/год | D25: Заявка £96–£260 (горячая еда £260) + продление; RBKC.
A27: 4. ОПЕР. РАСХОДЫ (в месяц, £, без НДС)
A28: Коммуналка (эл-во, газ, вода) | B28: 350 | C28: £/мес | D28: Оценка для малой точки.
A29: POS / касса (подписка) | B29: 30 | C29: £/мес | D29: SumUp/Square/Zettle POS.
A30: Эквайринг (комиссия, % от безнала) | B30: 0.016 | D30: Dojo ~0.8–1.3%, Square/Zettle 1.75%.
A31: Доля безналичных платежей | B31: 0.9 | D31: Лондон — почти весь оборот картой.
A32: Страхование | B32: 70 | C32: £/мес | D32: Public liability + оборудование.
A33: Вывоз мусора / waste | B33: 120 | C33: £/мес | D33: Commercial waste contract.
A34: Уборка / расходники | B34: 80 | C34: £/мес | D34: Химия, перчатки, санитария.
A35: Маркетинг | B35: 200 | C35: £/мес | D35: Соцсети, промо, вывеска.
A36: Бухгалтерия / accounting | B36: 200 | C36: £/мес | D36: Ltd отчётность, payroll, VAT returns.
A37: Ремонт / обслуживание | B37: 100 | C37: £/мес | D37: Оборудование, ТО.
A38: Прочее / непредвиденное | B38: 100 | C38: £/мес | D38: Буфер.
A40: 5. НАЛОГИ И АМОРТИЗАЦИЯ
A41: Corporation tax (small profits) | B41: 0.19 | D41: 19% при прибыли ≤£50k; далее marginal relief до 25%.
A42: Срок службы оборудования | B42: 5 | C42: лет | D42: Для амортизации CapEx.
A44: 6. ФИНАНСИРОВАНИЕ
A45: Собственные средства (equity) | B45: 40000 | C45: £ | D45: Вклад учредителей.
...

Sheet Меню и фудкост
A1: МЕНЮ И ФУДКОСТ — себестоимость 1 порции (опт, без НДС)
A2: Оптовые цены (Booker/Bidfood, СНГ-поставщики). Уточнить котировки у поставщика.
A3: Ингредиент | B3: Расход | C3: Ед. | D3: Цена опт (£/кг|£/шт) | E3: Стоимость, £ | F3: Примечание / источник
A4: Куриное филе (маринованное) | B4: 0.16 | C4: кг | D4: 7 | E4: =B4*D4 | F4: Опт грудка £6–£16.7/кг; берём средн. ~£7.
A5: Армянский лаваш (лист) | B5: 1 | C5: шт | D5: 0.55 | E5: =B5*D5 | F5: СНГ-поставщики (Babushka/Jolly Grocer), опт.
A6: Майонезный соус (майо+чеснок) | B6: 0.045 | C6: кг | D6: 4 | E6: =B6*D6 | F6: Майонез оптом + специи.
A7: Томаты | B7: 0.045 | C7: кг | D7: 2.3 | E7: =B7*D7 | F7: Опт овощи.
A8: Огурцы (свежие/маринов.) | B8: 0.035 | C8: кг | D8: 1.9 | E8: =B8*D8 | F8: Опт.
A9: Капуста / салат | B9: 0.04 | C9: кг | D9: 1.3 | E9: =B9*D9 | F9: Опт.
A10: Лук репчатый | B10: 0.02 | C10: кг | D10: 0.95 | E10: =B10*D10 | F10: Опт.
A11: Морковь по-корейски | B11: 0.02 | C11: кг | D11: 3 | E11: =B11*D11 | F11: Готовый салат/заготовка.
A12: Картофель фри (внутрь) | B12: 0.05 | C12: кг | D12: 1.4 | E12: =B12*D12 | F12: Замор. фри, опт (московский стиль).
A13: Специи / масло / маринад | B13: 1 | C13: порц | D13: 0.12 | E13: =B13*D13 | F13: Усреднённо на порцию.
A14: Итого ингредиенты (нетто) | E14: =SUM(E4:E13)
A15: Упаковка (обёртка/фольга/пакет/салфетка) | E15: 0.35 | F15: Стандартная ставка НДС (возмещается).
A16: Себестоимость шаурмы (с упаковкой) | E16: =E14+E15
A18: НАПИТКИ / ДОПЫ
A19: Себестоимость напитка (банка/бутылка) | E19: 0.45
A20: Доля заказов с напитком (attach) | E20: 0.35
A21: Средняя себест. напитка на заказ | E21: =E19*E20
A23: СРЕДНЯЯ СЕБЕСТОИМОСТЬ ЗАКАЗА (нетто) | E23: =E16+E21
A24: Средний чек заказа, нетто (без НДС) | E24: ='Допущения'!$B$6/(1+'Допущения'!$B$7)
A25: Food cost, % от чека (нетто) | E25: ='Меню и фудкост'!E23/E24
A26: Маржинальный доход на заказ, нетто | E26: =E24-'Меню и фудкост'!E23

Sheet Выручка
A1: ВЫРУЧКА — помесячно, Год 1
A2: Порций/день = база × сезонность. Синие ячейки — вводные.
A3: Показатель | C3: Янв | D3: Фев | E3: Мар | F3: Апр | G3: Май | H3: Июн | I3: Июл | J3: Авг | K3: Сен | L3: Окт | M3: Ноя | N3: Дек | O3: Год
A4: Рабочих дней | C4: 26 | D4: 25 | E4: 28 | F4: 28 | G4: 29 | H4: 28 | I4: 29 | J4: 29 | K4: 28 | L4: 29 | M4: 27 | N4: 26 | O4: =SUM(C4:N4)
A5: Сезонный коэффициент | C5: 0.85 | D5: 0.85 | E5: 0.95 | F5: 1 | G5: 1.05 | H5: 1.1 | I5: 1.15 | J5: 1.15 | K5: 1.05 | L5: 1 | M5: 0.9 | N5: 0.95 | O5: =AVERAGE(C5:N5)
A6: Порций/день | C6: ='Допущения'!$B$5*C5 | D6: ='Допущения'!$B$5*D5 | E6: ='Допущения'!$B$5*E5 | F6: ='Допущения'!$B$5*F5 | G6: ='Допущения'!$B$5*G5 | H6: ='Допущения'!$B$5*H5 | I6: ='Допущения'!$B$5*I5 | J6: ='Допущения'!$B$5*J5 | ... N6: ='Допущения'!$B$5*N5 | O6: =AVERAGE(C6:N6)
A7: Порций в месяц | C7: =C6*C4 | D7: =D6*D4 | E7: =E6*E4 | F7: =F6*F4 | G7: =G6*G4 | H7: =H6*H4 | I7: =I6*I4 | J7: =J6*J4 | ... N7: =N6*N4 | O7: =SUM(C7:N7)
A8: Средний чек, с НДС | C8: ='Допущения'!$B$6 | D8: ='Допущения'!$B$6 | E8: ='Допущения'!$B$6 | F8: ='Допущения'!$B$6 | G8: ='Допущения'!$B$6 | H8: ='Допущения'!$B$6 | I8: ='Допущения'!$B$6 | J8: ='Допущения'!$B$6 | ... O8: ='Допущения'!$B$6
A9: Выручка брутто (с НДС) | C9: =C7*C8 | D9: =D7*D8 | E9: =E7*E8 | F9: =F7*F8 | G9: =G7*G8 | H9: =H7*H8 | I9: =I7*I8 | J9: =J7*J8 | ... N9: =N7*N8 | O9: =SUM(C9:N9)
A10: НДС с продаж (20%) | C10: =C9*'Допущения'!$B$7/(1+'Допущения'!$B$7) | D10: =D9*'Допущения'!$B$7/(1+'Допущения'!$B$7) | E10: =E9*'Допущения'!$B$7/(1+'Допущения'!$B$7) | F10: =F9*'Допущения'!$B$7/(1+'Допущения'!$B$7) | G10: =G9*'Допущения'!$B$7/(1+'Допущения'!$B$7) | H10: =H9*'Допущения'!$B$7/(1+'Допущения'!$B$7) | I10: =I9*'Допущения'!$B$7/(1+'Допущения'!$B$7) | J10: =J9*'Допущения'!$B$7/(1+'Допущения'!$B$7) | ... N10: =N9*'Допущения'!$B$7/(1+'Допущения'!$B$7) | O10: =SUM(C10:N10)
A11: Выручка нетто (без НДС) | C11: =C9-C10 | D11: =D9-D10 | E11: =E9-E10 | F11: =F9-F10 | G11: =G9-G10 | H11: =H9-H10 | I11: =I9-I10 | J11: =J9-J10 | ... N11: =N9-N10 | O11: =SUM(C11:N11)

Sheet Персонал
A1: ПЕРСОНАЛ И ФОТ (Год 1)
A2: Показатель | B2: Значение | C2: Комментарий
A3: Человеко-часов в день | B3: ='Допущения'!$B$13 | C3: Из «Допущений».
A4: Рабочих дней в году | B4: ='Выручка'!$O$4 | C4: Сумма по «Выручке».
A5: Человеко-часов в год | B5: =B3*B4 | C5: =часы/день × дней.
A6: Ставка оплаты, £/ч | B6: ='Допущения'!$B$14 | C6: NLW 21+ 2026.
A7: Годовой ФОТ (gross) | B7: =B5*B6 | C7: Фонд оплаты труда, брутто.
A8: — порог NIC суммарно | B8: ='Допущения'!$B$17*'Допущения'!$B$15 | C8: ST × число сотрудников.
A9: Employer NIC (до вычета) | B9: =MAX(0,B7-B8)*'Допущения'!$B$16 | C9: 15% сверх порога.
A10: Employment Allowance | B10: =MIN(B9,'Допущения'!$B$18) | C10: Вычет из NIC (до £10,500).
A11: Employer NIC к уплате | B11: =B9-B10 | C11: NIC после вычета.
A12: — порог пенсии суммарно | B12: ='Допущения'!$B$20*'Допущения'!$B$15 | C12: Нижний порог × сотрудников.
A13: Пенсионные взносы работодателя | B13: =MAX(0,B7-B12)*'Допущения'!$B$19 | C13: 3% на qualifying earnings.
A14: ИТОГО расходы на персонал | B14: =B7+B11+B13 | C14: ФОТ + NIC + пенсия.

Sheet Опер. расходы
A1: ОПЕР. РАСХОДЫ — годовые (Год 1), без НДС
A2: Статья | B2: В месяц | C2: В год | D2: Комментарий
A3: Аренда места / pitch | B3: ='Допущения'!$B$23 | C3: =B3*12 | D3: Ежемесячная аренда/pitch fee.
A4: Лицензия street trading | B4: ='Допущения'!$B$25/12 | C4: ='Допущения'!$B$25 | D4: Годовая лицензия / продление.
A5: Коммуналка | B5: ='Допущения'!$B$28 | C5: =B5*12 | D5: Эл-во, газ, вода.
A6: POS / касса | B6: ='Допущения'!$B$29 | C6: =B6*12 | D6: Подписка POS.
A7: Эквайринг (комиссия) | B7: =C7/12 | C7: ='Выручка'!$O$9*'Допущения'!$B$31*'Допущения'!$B$30 | D7: Брутто-оборот × доля безнала × комиссия.
A8: Страхование | B8: ='Допущения'!$B$32 | C8: =B8*12 | D8: Public liability + оборудование.
A9: Вывоз мусора / waste | B9: ='Допущения'!$B$33 | C9: =B9*12 | D9: Commercial waste.
A10: Уборка / расходники | B10: ='Допущения'!$B$34 | C10: =B10*12 | D10: Санитария, расходники.
A11: Маркетинг | B11: ='Допущения'!$B$35 | C11: =B11*12 | D11: Промо, соцсети.
A12: Бухгалтерия | B12: ='Допущения'!$B$36 | C12: =B12*12 | D12: Отчётность, payroll, VAT.
A13: Ремонт / обслуживание | B13: ='Допущения'!$B$37 | C13: =B13*12 | D13: ТО оборудования.
A14: Прочее | B14: ='Допущения'!$B$38 | C14: =B14*12 | D14: Буфер.
A15: ИТОГО опер. расходы | B15: =SUM(B3:B14) | C15: =SUM(C3:C14)
A17: Справочно: база вход. НДС (станд. ставка) | C17: =C5+C6+C7+C9+C10+C11+C12+C13+C14+'Меню и фудкост'!E15*'Выручка'!$O$7 | D17: Аренда/страхование/лицензия — без вход. НДС (exempt/вне НДС).

Sheet Стартовые вложения
A1: СТАРТОВЫЕ ВЛОЖЕНИЯ (CapEx) И ФИНАНСИРОВАНИЕ
A2: Статья | B2: Сумма, £ | C2: Аморт.? | D2: Комментарий
A3: Киоск / контейнер (покупка/переоборуд.) | B3: 25000 | C3: да | D3: Основной актив.
A4: Оборудование (гриль-шаурма, холод., витрина, фритюр) | B4: 12000 | C4: да | D4: Кухонное оборудование.
A5: Мелкое оборудование / инвентарь | B5: 2500 | C5: да | D5: Ножи, доски, посуда.
A6: Вывеска / брендинг | B6: 3000 | C6: да | D6: Оформление точки.
A7: Ремонт / подготовка места | B7: 4000 | C7: нет | D7: Fit-out, подключения.
A8: Первичные лицензии / регистрация | B8: 1000 | C8: нет | D8: Street trading, food reg., компания.
A9: Первичный сток (продукты) | B9: 1500 | C9: нет | D9: Стартовый запас.
A10: Резерв / непредвиденное | B10: 3000 | C10: нет | D10: Буфер.
A11: Депозит аренды | B11: ='Допущения'!$B$23*'Допущения'!$B$24 | C11: нет | D11: Возвратный депозит (мес × аренда).
A12: Оборотный капитал (буфер) | B12: 6000 | C12: нет | D12: Запас на первые месяцы.
A13: ИТОГО стартовые вложения | B13: =SUM(B3:B12)
A14: Амортизируемая база (оборудование) | B14: =B3+B4+B5+B6
A15: Амортизация в год | B15: ='Стартовые вложения'!$B$14/'Допущения'!$B$42
A17: ФИНАНСИРОВАНИЕ
A18: Собственные средства | B18: ='Допущения'!$B$45
A19: Кредит / займ | B19: ='Допущения'!$B$46
A20: Итого финансирование | B20: ='Допущения'!$B$45+'Допущения'!$B$46
A21: Профицит / (дефицит) финансирования | B21: ='Стартовые вложения'!$B$20-'Стартовые вложения'!$B$13

Sheet P&L (3 года)
A1: ОТЧЁТ О ПРИБЫЛЯХ И УБЫТКАХ (P&L), £ без НДС
A2: Показатель | B2: Год 1 | C2: Год 2 | D2: Год 3 | E2: Комментарий
A3: Выручка брутто (с НДС) | B3: ='Выручка'!$O$9 | C3: =B3*(1+'Допущения'!$B$8) | D3: =C3*(1+'Допущения'!$B$8) | E3: Из «Выручки»; рост по допущению.
A4: НДС с продаж | B4: =-'Выручка'!$O$10 | C4: =B4*(1+'Допущения'!$B$8) | D4: =C4*(1+'Допущения'!$B$8) | E4: Выходной НДС (20%).
A5: Выручка нетто | B5: ='Выручка'!$O$11 | C5: =B5*(1+'Допущения'!$B$8) | D5: =C5*(1+'Допущения'!$B$8) | E5: Брутто минус НДС.
A6: Себестоимость (COGS) | B6: =-'Выручка'!$O$7*'Меню и фудкост'!E23 | C6: =B6*(1+'Допущения'!$B$8) | D6: =C6*(1+'Допущения'!$B$8) | E6: Порций × себест. заказа (опт).
A7: Валовая прибыль | B7: =B5+B6 | C7: =B7*(1+'Допущения'!$B$8) | D7: =C7*(1+'Допущения'!$B$8) | E7: Нетто-выручка − COGS.
A8: Валовая маржа, % | B8: =B7/B5 | C8: =C7/C5 | D8: =D7/D5 | E8: Валовая прибыль / нетто-выручка.
A9: Аренда + лицензия | B9: =-('Опер. расходы'!$C$3+'Опер. расходы'!$C$4) | C9: =B9*(1+'Допущения'!$B$8) | D9: =C9*(1+'Допущения'!$B$8) | E9: Pitch + street trading licence.
A10: Эквайринг + POS | B10: =-('Опер. расходы'!$C$7+'Опер. расходы'!$C$6) | C10: =B10*(1+'Допущения'!$B$8) | D10: =C10*(1+'Допущения'!$B$8) | E10: Комиссии карт + касса.
A11: Коммуналка | B11: =-'Опер. расходы'!$C$5 | C11: =B11*(1+'Допущения'!$B$8) | D11: =C11*(1+'Допущения'!$B$8)
A12: Прочие опер. расходы | B12: =-('Опер. расходы'!$C$8+'Опер. расходы'!$C$9+'Опер. расходы'!$C$10+'Опер. расходы'!$C$11+'Опер. расходы'!$C$12+'Опер. расходы'!$C$13+'Опер. расходы'!$C$14) | C12: =B12*(1+'Допущения'!$B$8) | D12: =C12*(1+'Допущения'!$B$8) | E12: Страховка, waste, уборка, маркетинг, бухг., ремонт, прочее.
A13: Расходы на персонал | B13: =-'Персонал'!$B$14 | C13: =B13*(1+'Допущения'!$B$8) | D13: =C13*(1+'Допущения'!$B$8) | E13: ФОТ + NIC + пенсия.
A14: EBITDA | B14: =B7+B9+B10+B11+B12+B13 | C14: =B14*(1+'Допущения'!$B$8) | D14: =C14*(1+'Допущения'!$B$8) | E14: Прибыль до аморт., %, налога.
A15: Амортизация | B15: =-'Стартовые вложения'!$B$15 | C15: =B15 | D15: =C15 | E15: Равномерно по сроку службы.
A16: Проценты по кредиту | B16: =-'Допущения'!$B$46*'Допущения'!$B$47 | C16: =-'Допущения'!$B$46*'Допущения'!$B$47*0.66 | D16: =-'Допущения'!$B$46*'Допущения'!$B$47*0.33 | E16: Убывают по мере погашения (упрощённо).
A17: Прибыль до налога (PBT) | B17: =B14+B15+B16 | C17: =B17*(1+'Допущения'!$B$8) | D17: =C17*(1+'Допущения'!$B$8)
A18: Corporation tax | B18: =-MAX(0,B17)*'Допущения'!$B$41 | C18: =-MAX(0,C17)*'Допущения'!$B$41 | D18: =-MAX(0,D17)*'Допущения'!$B$41 | E18: 19% (small profits).
A19: ЧИСТАЯ ПРИБЫЛЬ | B19: =B17+B18 | C19: =B19*(1+'Допущения'!$B$8) | D19: =C19*(1+'Допущения'!$B$8)
A20: Чистая маржа, % | B20: =B19/B5 | C20: =C19/C5 | D20: =D19/D5 | E20: Чистая прибыль / нетто-выручка.

Sheet Cash flow
A1: ДВИЖЕНИЕ ДЕНЕЖНЫХ СРЕДСТВ (Cash flow) — Год 1, £
A2: Мес.0 — запуск (CapEx, финансирование). Включены обслуживание кредита (проценты+тело) и квартальный НДС.
A3: Показатель | B3: Мес.0 | C3: Янв | D3: Фев | E3: Мар | F3: Апр | G3: Май | H3: Июн | I3: Июл | J3: Авг | K3: Сен | L3: Окт | M3: Ноя | N3: Дек | O3: Год
A4: Поступления (брутто, с НДС) | B4: 0 | C4: ='Выручка'!C9 | D4: ='Выручка'!D9 | E4: ='Выручка'!E9 | F4: ='Выручка'!F9 | G4: ='Выручка'!G9 | H4: ='Выручка'!H9 | I4: ='Выручка'!I9 | J4: ='Выручка'!J9 | ... N4: ='Выручка'!N9 | O4: =B4+SUM(C4:N4)
A5: Финансирование (equity+кредит) | B5: ='Стартовые вложения'!$B$20 | C5: 0 | D5: 0 | E5: 0 | F5: 0 | G5: 0 | H5: 0 | I5: 0 | J5: 0 | K5: 0 | L5: 0 | M5: 0 | N5: 0 | O5: =B5+SUM(C5:N5)
A6: CapEx / стартовые вложения | B6: =-'Стартовые вложения'!$B$13 | C6: 0 | D6: 0 | E6: 0 | F6: 0 | G6: 0 | H6: 0 | I6: 0 | J6: 0 | K6: 0 | L6: 0 | M6: 0 | N6: 0 | O6: =B6+SUM(C6:N6)
A7: Себестоимость (COGS) | B7: 0 | C7: =-'Выручка'!C7*'Меню и фудкост'!E23 | D7: =-'Выручка'!D7*'Меню и фудкост'!E23 | E7: =-'Выручка'!E7*'Меню и фудкост'!E23 | F7: =-'Выручка'!F7*'Меню и фудкост'!E23 | G7: =-'Выручка'!G7*'Меню и фудкост'!E23 | H7: =-'Выручка'!H7*'Меню и фудкост'!E23 | I7: =-'Выручка'!I7*'Меню и фудкост'!E23 | J7: =-'Выручка'!J7*'Меню и фудкост'!E23 | K7: =-'Выручка'!K7*'Меню и фудкост'!E23 | L7: =-'Выручка'!L7*'Меню и фудкост'!E23 | M7: =-'Выручка'!M7*'Меню и фудкост'!E23 | N7: =-'Выручка'!N7*'Меню и фудкост'!E23 | O7: =B7+SUM(C7:N7)
A8: Персонал (ФОТ+NIC+пенсия) | B8: 0 | C8: =-'Персонал'!$B$14/12 | D8: =-'Персонал'!$B$14/12 | E8: =-'Персонал'!$B$14/12 | F8: =-'Персонал'!$B$14/12 | G8: =-'Персонал'!$B$14/12 | H8: =-'Персонал'!$B$14/12 | I8: =-'Персонал'!$B$14/12 | J8: =-'Персонал'!$B$14/12 | ... N8: =-'Персонал'!$B$14/12 | O8: =B8+SUM(C8:N8)
A9: Аренда + лицензия | B9: 0 | C9: =-'Допущения'!$B$23-'Допущения'!$B$25/12 | D9: =-'Допущения'!$B$23-'Допущения'!$B$25/12 | E9: =-'Допущения'!$B$23-'Допущения'!$B$25/12 | F9: =-'Допущения'!$B$23-'Допущения'!$B$25/12 | G9: =-'Допущения'!$B$23-'Допущения'!$B$25/12 | H9: =-'Допущения'!$B$23-'Допущения'!$B$25/12 | I9: =-'Допущения'!$B$23-'Допущения'!$B$25/12 | J9: =-'Допущения'!$B$23-'Допущения'!$B$25/12 | ... N9: =-'Допущения'!$B$23-'Допущения'!$B$25/12 | O9: =B9+SUM(C9:N9)
A10: Прочие опер. расходы | B10: 0 | C10: =-('Допущения'!$B$28+'Допущения'!$B$29+'Допущения'!$B$32+'Допущения'!$B$33+'Допущения'!$B$34+'Допущения'!$B$35+'Допущения'!$B$36+'Допущения'!$B$37+'Допущения'!$B$38) | D10: =-('Допущения'!$B$28+'Допущения'!$B$29+'Допущения'!$B$32+'Допущения'!$B$33+'Допущения'!$B$34+'Допущения'!$B$35+'Допущения'!$B$36+'Допущения'!$B$37+'Допущения'!$B$38) | E10: =-('Допущения'!$B$28+'Допущения'!$B$29+'Допущения'!$B$32+'Допущения'!$B$33+'Допущения'!$B$34+'Допущения'!$B$35+'Допущения'!$B$36+'Допущения'!$B$37+'Допущения'!$B$38) | F10: =-('Допущения'!$B$28+'Допущения'!$B$29+'Допущения'!$B$32+'Допущения'!$B$33+'Допущения'!$B$34+'Допущения'!$B$35+'Допущения'!$B$36+'Допущения'!$B$37+'Допущения'!$B$38) | G10: =-('Допущения'!$B$28+'Допущения'!$B$29+'Допущения'!$B$32+'Допущения'!$B$33+'Допущения'!$B$34+'Допущения'!$B$35+'Допущения'!$B$36+'Допущения'!$B$37+'Допущения'!$B$38) | H10: =-('Допущения'!$B$28+'Допущения'!$B$29+'Допущения'!$B$32+'Допущения'!$B$33+'Допущения'!$B$34+'Допущения'!$B$35+'Допущения'!$B$36+'Допущения'!$B$37+'Допущения'!$B$38) | I10: =-('Допущения'!$B$28+'Допущения'!$B$29+'Допущения'!$B$32+'Допущения'!$B$33+'Допущения'!$B$34+'Допущения'!$B$35+'Допущения'!$B$36+'Допущения'!$B$37+'Допущения'!$B$38) | J10: =-('Допущения'!$B$28+'Допущения'!$B$29+'Допущения'!$B$32+'Допущения'!$B$33+'Допущения'!$B$34+'Допущения'!$B$35+'Допущения'!$B$36+'Допущения'!$B$37+'Допущения'!$B$38) | ... N10: =-('Допущения'!$B$28+'Допущения'!$B$29+'Допущения'!$B$32+'Допущения'!$B$33+'Допущения'!$B$34+'Допущения'!$B$35+'Допущения'!$B$36+'Допущения'!$B$37+'Допущения'!$B$38) | O10: =B10+SUM(C10:N10)
A11: Эквайринг (комиссия) | B11: 0 | C11: =-'Выручка'!C9*'Допущения'!$B$31*'Допущения'!$B$30 | D11: =-'Выручка'!D9*'Допущения'!$B$31*'Допущения'!$B$30 | E11: =-'Выручка'!E9*'Допущения'!$B$31*'Допущения'!$B$30 | F11: =-'Выручка'!F9*'Допущения'!$B$31*'Допущения'!$B$30 | G11: =-'Выручка'!G9*'Допущения'!$B$31*'Допущения'!$B$30 | H11: =-'Выручка'!H9*'Допущения'!$B$31*'Допущения'!$B$30 | I11: =-'Выручка'!I9*'Допущения'!$B$31*'Допущения'!$B$30 | J11: =-'Выручка'!J9*'Допущения'!$B$31*'Допущения'!$B$30 | ... N11: =-'Выручка'!N9*'Допущения'!$B$31*'Допущения'!$B$30 | O11: =B11+SUM(C11:N11)
A12: Проценты по кредиту | B12: 0 | C12: =-'Допущения'!$B$46*'Допущения'!$B$47/12 | D12: =-'Допущения'!$B$46*'Допущения'!$B$47/12 | E12: =-'Допущения'!$B$46*'Допущения'!$B$47/12 | F12: =-'Допущения'!$B$46*'Допущения'!$B$47/12 | G12: =-'Допущения'!$B$46*'Допущения'!$B$47/12 | H12: =-'Допущения'!$B$46*'Допущения'!$B$47/12 | I12: =-'Допущения'!$B$46*'Допущения'!$B$47/12 | J12: =-'Допущения'!$B$46*'Допущения'!$B$47/12 | ... N12: =-'Допущения'!$B$46*'Допущения'!$B$47/12 | O12: =B12+SUM(C12:N12)
A13: Погашение тела кредита | B13: 0 | C13: =-'Допущения'!$B$46/'Допущения'!$B$48/12 | D13: =-'Допущения'!$B$46/'Допущения'!$B$48/12 | E13: =-'Допущения'!$B$46/'Допущения'!$B$48/12 | F13: =-'Допущения'!$B$46/'Допущения'!$B$48/12 | G13: =-'Допущения'!$B$46/'Допущения'!$B$48/12 | H13: =-'Допущения'!$B$46/'Допущения'!$B$48/12 | I13: =-'Допущения'!$B$46/'Допущения'!$B$48/12 | J13: =-'Допущения'!$B$46/'Допущения'!$B$48/12 | ... N13: =-'Допущения'!$B$46/'Допущения'!$B$48/12 | O13: =B13+SUM(C13:N13)
A14: НДС к уплате (квартально) | B14: 0 | C14: 0 | D14: 0 | E14: =-(('Выручка'!C10+'Выручка'!D10+'Выручка'!E10)-('Опер. расходы'!$C$17/12*3*'Допущения'!$B$7/(1+'Допущения'!$B$7))) | F14: 0 | G14: 0 | H14: =-(('Выручка'!F10+'Выручка'!G10+'Выручка'!H10)-('Опер. расходы'!$C$17/12*3*'Допущения'!$B$7/(1+'Допущения'!$B$7))) | I14: 0 | J14: 0 | K14: =-(('Выручка'!I10+'Выручка'!J10+'Выручка'!K10)-('Опер. расходы'!$C$17/12*3*'Допущения'!$B$7/(1+'Допущения'!$B$7))) | L14: 0 | M14: 0 | N14: =-(('Выручка'!L10+'Выручка'!M10+'Выручка'!N10)-('Опер. расходы'!$C$17/12*3*'Допущения'!$B$7/(1+'Допущения'!$B$7))) | O14: =B14+SUM(C14:N14)
A15: Чистый денежный поток | B15: =SUM(B4:B14) | C15: =SUM(C4:C14) | D15: =SUM(D4:D14) | E15: =SUM(E4:E14) | F15: =SUM(F4:F14) | G15: =SUM(G4:G14) | H15: =SUM(H4:H14) | I15: =SUM(I4:I14) | ... N15: =SUM(N4:N14) | O15: =B15+SUM(C15:N15)
A16: Остаток денежных средств (накопл.) | B16: =B15 | C16: =B16+C15 | D16: =C16+D15 | E16: =D16+E15 | F16: =E16+F15 | G16: =F16+G15 | H16: =G16+H15 | I16: =H16+I15 | J16: =I16+J15 | ... N16: =M16+N15
A18: Справка: Corporation tax начислен | B18: =-'P&L (3 года)'!$B$18 | C18: Не входит в поток Года 1: CT уплачивается через 9 мес + 1 день после конца отчётного года (т.е. в Год 2).

Sheet Безубыточность
A1: ТОЧКА БЕЗУБЫТОЧНОСТИ И СЦЕНАРИИ
A2: Маржинальный анализ: постоянные затраты покрываются маржой на заказ.
A3: Средний чек, нетто | B3: ='Допущения'!$B$6/(1+'Допущения'!$B$7) | C3: Без НДС.
A4: Переменные затраты на заказ | B4: ='Меню и фудкост'!E23+('Допущения'!$B$6*'Допущения'!$B$31*'Допущения'!$B$30) | C4: Себест. заказа + комиссия эквайринга.
A5: Маржинальный доход на заказ | B5: =B3-B4 | C5: Contribution margin.
A6: Постоянные затраты в год | B6: ='Опер. расходы'!$C$15+'Персонал'!$B$14+'Стартовые вложения'!$B$15+'Допущения'!$B$46*'Допущения'!$B$47-('Выручка'!$O$9*'Допущения'!$B$31*'Допущения'!$B$30) | C6: Опер.расходы+персонал+аморт.+% (эквайринг вынесен в переменные).
A7: Точка безубыточности (заказов/год) | B7: =B6/B5
A8: Точка безубыточности (заказов/день) | B8: =B7/'Выручка'!$O$4
A9: Текущая база (заказов/день) | B9: ='Допущения'!$B$5 | C9: Из «Допущений».
A10: Запас прочности | B10: =('Допущения'!$B$5-B8)/'Допущения'!$B$5 | C10: Насколько база выше безубыточности.
A12: СЦЕНАРИИ (год)
A13: Показатель | B13: Пессимистичный | C13: Базовый | D13: Оптимистичный
A14: Порций/день (ввод) | B14: 60 | C14: 90 | D14: 120
A15: Выручка нетто | B15: =B14*'Выручка'!$O$4*$B$3 | C15: =C14*'Выручка'!$O$4*$B$3 | D15: =D14*'Выручка'!$O$4*$B$3
A16: Маржинальный доход | B16: =B14*'Выручка'!$O$4*$B$5 | C16: =C14*'Выручка'!$O$4*$B$5 | D16: =D14*'Выручка'!$O$4*$B$5
A17: − Постоянные затраты | B17: =-$B$6 | C17: =-$B$6 | D17: =-$B$6
A18: Прибыль до налога | B18: =B16-$B$6 | C18: =C16-$B$6 | D18: =D16-$B$6
A19: Corporation tax | B19: =-MAX(0,B18)*'Допущения'!$B$41 | C19: =-MAX(0,C18)*'Допущения'!$B$41 | D19: =-MAX(0,D18)*'Допущения'!$B$41
A20: ЧИСТАЯ ПРИБЫЛЬ | B20: =B18+B19 | C20: =C18+C19 | D20: =D18+D19

Sheet Налоги
A1: НАЛОГИ И ОБЯЗАТЕЛЬНЫЕ ПЛАТЕЖИ (Год 1)
A2: Статья | B2: Сумма/ставка | C2: Пояснение и источник
A3: НДС (VAT)
A4: Ставка НДS (горячая еда навынос) | B4: ='Допущения'!$B$7 | C4: HMRC VAT Notice 701/14 — стандартная ставка 20%.
A5: Выходной НДС (с продаж), год | B5: ='Выручка'!$O$10 | C5: 20/120 от брутто-выручки.
A6: Входной НДС к возмещению (оценка) | B6: ='Опер. расходы'!$C$17*'Допущения'!$B$7/(1+'Допущения'!$B$7) | C6: По упаковке/коммуналке/услугам; сырьё — нулевая ставка.
A7: НДС к уплате в бюджет, год | B7: =B5-B6 | C7: Выходной минус входной.
A8: Порог регистрации по НДС | B8: 90000 | C8: Обязательная регистрация при обороте >£90,000.
A10: CORPORATION TAX
A11: Прибыль до налога (PBT), Год 1 | B11: ='P&L (3 года)'!$B$17 | C11: Из P&L.
A12: Ставка (small profits) | B12: ='Допущения'!$B$41 | C12: 19% при прибыли ≤£50k; marginal relief £50k–£250k (эфф. 26.5%), 25% свыше £250k.
A13: Corporation tax, Год 1 | B13: =MAX(0,B11)*B12 | C13: Оценка по ставке small profits.
A15: ЗАРПЛАТНЫЕ НАЛОГИ (payroll)
A16: Employer NIC к уплате, год | B16: ='Персонал'!$B$11 | C16: 15% сверх £5,000/сотр., минус Employment Allowance (£10,500).
A17: Пенсионные взносы работодателя, год | B17: ='Персонал'!$B$13 | C17: Auto-enrolment, 3% на qualifying earnings.
A18: Итого зарплатные налоги/взносы | B18: =B16+B17
A20: BUSINESS RATES
A21: Business rates (оценка) | B21: 0 | C21: Малый киоск: RV<£12,000 → 100% Small Business Rate Relief (£0). Уличная точка платит pitch fee вместо rates.
A23: ИТОГО НАЛОГОВ И ВЗНОСОВ (Год 1) | B23: =B7+B13+B18+B21 | C23: НДС + Corp tax + NIC + пенсия + rates.
